Workbook

Sheet Gasoline and electric vehicles
A1: kg/t conversion factor | B1: 1000
A2: g/kg | B2: 1000 | AE2: Gas Vehicle spreadsheet calculations | AF2: Gas Vehicle Open LCA | AG2: Electric Vehicle spreadsheet calculations | AH2: Electric Vehicle Open LCA | AI2: Electric Vehicle - Wind spreadsheet calculations | AJ2: Electric Vehicle-Wind Open LCA | AK2: Electric Vehicle - Photovoltaic spreadsheet calculations | AL2: Electric Vehicle - Photovoltaic Open LCA | AM2: Electric Vehicle - Hard coal spreadsheet calculations | AP2: GHG CO2equ. kgCO2equ over lifetime | AQ2: Cumulative graph | AW2: GHG CO2equ. kgCO2equ/FU | AX2: Graph per FU
A4: Vehicle lifespan (km/vehicle) | B4: 150000 | AD4: Lifetime distance km | AE4: 150000 | AG4: =1.5*$AE4 -> 225000 | AI4: =1.5*$AE4 -> 225000 | AK4: =1.5*$AE4 -> 225000 | AM4: =1.5*$AE4 -> 225000
A5: Transportation by Gas Vehicle FU= 1 vehicle km Life Cycle stage (150,000 km lifespan) | B5: Quantity original unit | C5: Quantity per FU | D5: Unit | E5: Energy/Unit [MJ/Unit] | F5: Energy per FU [MJ/FU] | G5: fraction | H5: CO2/Unit [kg/unit] | I5: CO2 fossil/FU | J5: fraction2 | K5: Check g CO2/MJ | L5: CO2equ/Unit [kg/unit]2 | M5: CO2equ./FU | N5: fraction3 | P5: Energy MJ/FU | Q5: Gas Vehicle | R5: Electric Vehicle | S5: Electric Vehicle - Wind | T5: Electric Vehicle - Photovoltaic | U5: Electric Vehicle - hard coal | W5: Fossil CO2 kgCO2/FU | X5: Gas Vehicle | Y5: Electric Vehicle | Z5: Electric Vehicle - Wind | AA5: Electric Vehicle - Photovoltaic | AB5: Electric Vehicle - hard coal | AD5: GHG CO2equ. kgCO2equ/FU | AE5: Gas Vehicle | AG5: Electric Vehicle - EU mix | AI5: Electric Vehicle - Wind | AK5: Electric Vehicle - Photovoltaic | AM5: Electric Vehicle - hard coal | AP5: Distance over Lifetime | AQ5: Gas Vehicle | AR5: Electric Vehicle - EU mix | AS5: Electric Vehicle - Wind | AT5: Electric Vehicle - Photovoltaic | AU5: Electric Vehicle - Hard coal | AW5: Distance over Lifetime | AX5: Gas Vehicle | AY5: Electric Vehicle | AZ5: Electric Vehicle - Wind | BA5: Electric Vehicle - Photovoltaic | BB5: Electric Vehicle - Hard coal
A6: Manufacturing (Materials + Processing) | B6: per vehicle over lifespan | C6: per FU | P6: Car manufacturing | Q6: =SUM(F7:F31) -> 0.60021733 | R6: =SUM($F$54:$F$67) -> 0.57011251 | S6: =SUM($F$54:$F$67) -> 0.57011251 | T6: =SUM($F$54:$F$67) -> 0.57011251 | U6: =SUM($F$54:$F$67) -> 0.57011251 | W6: Car manufacturing | X6: =SUM(I7:I31) -> 0.034617172 | Y6: =SUM($I$54:$I$67) -> 0.035992784 | Z6: =SUM($I$54:$I$67) -> 0.035992784 | AA6: =SUM($I$54:$I$67) -> 0.035992784 | AB6: =SUM($I$54:$I$67) -> 0.035992784 | AD6: Car manufacturing | AE6: =SUM(M7:M31) -> 0.038914035 | AG6: =SUM($M$54:$M$67) -> 0.04077092 | AI6: =SUM($M$54:$M$67) -> 0.04077092 | AK6: =SUM($M$54:$M$67) -> 0.04077092 | AM6: =SUM($M$54:$M$67) -> 0.04077092 | AP6: 0 | AQ6: =SUM(AE6:AE7)*AE4 -> 5970.006 | AR6: =SUM(AG6:AG7)*AG4 -> 9298.2131 | AS6: =SUM(AI6:AI7)*AI4 -> 9298.2131 | AT6: =SUM(AK6:AK7)*AK4 -> 9298.2131 | AU6: =SUM(AM6:AM7)*AM4 -> 9298.2131 | AW6: 0.01 | AX6: =AQ6/$AW6 -> 597000.6 | AY6: =AR6/$AW6 -> 929821.31 | AZ6: =AS6/$AW6 -> 929821.31 | BA6: =AT6/$AW6 -> 929821.31 | BB6: =AU6/$AW6 -> 929821.31
A7: alkyd paint, white, without solvent, in 60% solution state | B7: 4.4 | C7: =B7/$B$4 -> 2.9333333e-05 | D7: kg | E7: =Processes!H4 -> 61.912708 | F7: =E7*$C7 -> 0.0018161061 | G7: =F7/F$47 -> 0.00045621398 | H7: =Processes!G4 -> 4.8913828 | I7: =H7*$C7 -> 0.00014348056 | J7: =I7/I$47 -> 0.00054057316 | K7: =I7/F7*$B$2 -> 79.004505 | L7: =Processes!J4 -> 5.4372182 | M7: =L7*$C7 -> 0.00015949173 | N7: =M7/M$47 -> 0.00058418741 | P7: Car transportation | Q7: =SUM(F33:F35) -> 0.012538957 | R7: =SUM($F$70:$F$72) -> 0.0078671987 | S7: =SUM($F$70:$F$72) -> 0.0078671987 | T7: =SUM($F$70:$F$72) -> 0.0078671987 | U7: =SUM($F$70:$F$72) -> 0.0078671987 | W7: Car transportation | X7: =SUM(I33:I35) -> 0.00085108588 | Y7: =SUM($I$70:$I$72) -> 0.00053237727 | Z7: =SUM($I$70:$I$72) -> 0.00053237727 | AA7: =SUM($I$70:$I$72) -> 0.00053237727 | AB7: =SUM($I$70:$I$72) -> 0.00053237727 | AD7: Car transportation | AE7: =SUM(M33:M35) -> 0.00088600506 | AG7: =SUM($M$70:$M$72) -> 0.00055447131 | AI7: =SUM($M$70:$M$72) -> 0.00055447131 | AK7: =SUM($M$70:$M$72) -> 0.00055447131 | AM7: =SUM($M$70:$M$72) -> 0.00055447131 | AP7: 1000 | AQ7: =AQ$6+AE$9*$AP7 -> 6202.1071 | AR7: =AR$6+AG$10*$AP7 -> 9409.6203 | AS7: =AS$6+AI$11*$AP7 -> 9301.9783 | AT7: =AT$6+AK$12*$AP7 -> 9318.5218 | AU7: =AU$6+AM$13*$AP7 -> 9560.5488 | AW7: =AP7 -> 1000 | AX7: =AQ7/$AW7 -> 6.2021071 | AY7: =AR7/$AW7 -> 9.4096203 | AZ7: =AS7/$AW7 -> 9.3019783 | BA7: =AT7/$AW7 -> 9.3185218 | BB7: =AU7/$AW7 -> 9.5605488
A8: aluminium, primary, ingot | B8: 54.4 | C8: =B8/$B$4 -> 0.00036266667 | D8: kg | E8: =Processes!H5 -> 218.89578 | F8: =E8*$C8 -> 0.079386201 | G8: =F8/F$47 -> 0.019942169 | H8: =Processes!G5 -> 19.24884 | I8: =H8*$C8 -> 0.0069809126 | J8: =I8/I$47 -> 0.026301082 | K8: =I8/F8*$B$2 -> 87.936096 | L8: =Processes!J5 -> 20.97429 | M8: =L8*$C8 -> 0.0076066758 | N8: =M8/M$47 -> 0.027861784 | P8: Car disposal | Q8: =SUM(F40:F44) -> 0.00040019259 | R8: =SUM($F$79:$F$82) -> 0.00023611308 | S8: =SUM($F$79:$F$82) -> 0.00023611308 | T8: =SUM($F$79:$F$82) -> 0.00023611308 | U8: =SUM($F$79:$F$82) -> 0.00023611308 | W8: Car disposal | X8: =SUM(I40:I44) -> 0.0011071191 | Y8: =SUM($I$79:$I$82) -> 8.0222474e-05 | Z8: =SUM($I$79:$I$82) -> 8.0222474e-05 | AA8: =SUM($I$79:$I$82) -> 8.0222474e-05 | AB8: =SUM($I$79:$I$82) -> 8.0222474e-05 | AD8: Car disposal | AE8: =SUM(M40:M44) -> 0.0011135382 | AG8: =SUM($M$79:$M$82) -> 0.00013944219 | AI8: =SUM($M$79:$M$82) -> 0.00013944219 | AK8: =SUM($M$79:$M$82) -> 0.00013944219 | AM8: =SUM($M$79:$M$82) -> 0.00013944219 | AP8: 2000 | AQ8: =AQ$6+AE$9*$AP8 -> 6434.2082 | AR8: =AR$6+AG$10*$AP8 -> 9521.0275 | AS8: =AS$6+AI$11*$AP8 -> 9305.7435 | AT8: =AT$6+AK$12*$AP8 -> 9338.8306 | AU8: =AU$6+AM$13*$AP8 -> 9822.8844 | AW8: =AP8 -> 2000 | AX8: =AQ8/$AW8 -> 3.2171041 | AY8: =AR8/$AW8 -> 4.7605138 | AZ8: =AS8/$AW8 -> 4.6528718 | BA8: =AT8/$AW8 -> 4.6694153 | BB8: =AU8/$AW8 -> 4.9114422
A9: chromium oxide, flakes | B9: 2.5 | C9: =B9/$B$4 -> 1.6666667e-05 | D9: kg | E9: =Processes!H6 -> 56.396524 | F9: =E9*$C9 -> 0.00093994206 | G9: =F9/F$47 -> 0.00023611765 | H9: =Processes!G6 -> 5.6316443 | I9: =H9*$C9 -> 9.3860738e-05 | J9: =I9/I$47 -> 0.00035362697 | K9: =I9/F9*$B$2 -> 99.858004 | L9: =Processes!J6 -> 6.0199005 | M9: =L9*$C9 -> 0.00010033167 | N9: =M9/M$47 -> 0.00036749554 | P9: Petrol gas | Q9: =F37 -> 3.3676643 | W9: Petrol gas | X9: =I37+I38 -> 0.22884764 | AD9: Petrol gas | AE9: =M37+M38 -> 0.2321011 | AP9: 3000 | AQ9: =AQ$6+AE$9*$AP9 -> 6666.3093 | AR9: =AR$6+AG$10*$AP9 -> 9632.4347 | AS9: =AS$6+AI$11*$AP9 -> 9309.5087 | AT9: =AT$6+AK$12*$AP9 -> 9359.1393 | AU9: =AU$6+AM$13*$AP9 -> 10085.22 | AW9: =AP9 -> 3000 | AX9: =AQ9/$AW9 -> 2.2221031 | AY9: =AR9/$AW9 -> 3.2108116 | AZ9: =AS9/$AW9 -> 3.1031696 | BA9: =AT9/$AW9 -> 3.1197131 | BB9: =AU9/$AW9 -> 3.36174
A10: sheet rolling, copper | B10: 21.2 | C10: =B10/$B$4 -> 0.00014133333 | D10: kg | E10: =Processes!H7 -> 74.579203 | F10: =E10*$C10 -> 0.010540527 | G10: =F10/F$47 -> 0.0026478276 | H10: =Processes!G7 -> 5.1792783 | I10: =H10*$C10 -> 0.00073200467 | J10: =I10/I$47 -> 0.0027578793 | K10: =I10/F10*$B$2 -> 69.446684 | L10: =Processes!J7 -> 5.8649728 | M10: =L10*$C10 -> 0.00082891616 | N10: =M10/M$47 -> 0.0030361597 | P10: Electric charging - RER | R10: =F74 -> 2.3577679 | W10: Electric charging - RER | Y10: =I74 -> 0.10403525 | AD10: Electric charging - RER | AG10: =M74 -> 0.11140719 | AP10: 5000 | AQ10: =AQ$6+AE$9*$AP10 -> 7130.5115 | AR10: =AR$6+AG$10*$AP10 -> 9855.2491 | AS10: =AS$6+AI$11*$AP10 -> 9317.0392 | AT10: =AT$6+AK$12*$AP10 -> 9399.7567 | AU10: =AU$6+AM$13*$AP10 -> 10609.891 | AW10: =AP10 -> 5000 | AX10: =AQ10/$AW10 -> 1.4261023 | AY10: =AR10/$AW10 -> 1.9710498 | AZ10: =AS10/$AW10 -> 1.8634078 | BA10: =AT10/$AW10 -> 1.8799513 | BB10: =AU10/$AW10 -> 2.1219783
A11: electronics, for control units | B11: 6.1 | C11: =B11/$B$4 -> 4.0666667e-05 | D11: kg | E11: =Processes!H8 -> 448.24729 | F11: =E11*$C11 -> 0.018228723 | G11: =F11/F$47 -> 0.0045791369 | H11: =Processes!G8 -> 27.933745 | I11: =H11*$C11 -> 0.0011359723 | J11: =I11/I$47 -> 0.0042798559 | K11: =I11/F11*$B$2 -> 62.31771 | L11: =Processes!J8 -> 31.49787 | M11: =L11*$C11 -> 0.0012809134 | N11: =M11/M$47 -> 0.0046917382 | P11: Electric charging - wind | S11: =F75 -> 0.050716201 | W11: Electric charging - wind | Z11: =I75 -> 0.0033340684 | AD11: Electric charging - wind | AI11: =M75 -> 0.0037652069 | AP11: 7000 | AQ11: =AQ$6+AE$9*$AP11 -> 7594.7137 | AR11: =AR$6+AG$10*$AP11 -> 10078.063 | AS11: =AS$6+AI$11*$AP11 -> 9324.5696 | AT11: =AT$6+AK$12*$AP11 -> 9440.3742 | AU11: =AU$6+AM$13*$AP11 -> 11134.563 | AW11: =AP11 -> 7000 | AX11: =AQ11/$AW11 -> 1.0849591 | AY11: =AR11/$AW11 -> 1.4397234 | AZ11: =AS11/$AW11 -> 1.3320814 | BA11: =AT11/$AW11 -> 1.3486249 | BB11: =AU11/$AW11 -> 1.5906518
A12: ethylene | B12: 19.4 | C12: =B12/$B$4 -> 0.00012933333 | D12: kg | E12: =Processes!H9 -> 66.770079 | F12: =E12*$C12 -> 0.0086355968 | G12: =F12/F$47 -> 0.0021693006 | H12: =Processes!G9 -> 1.1303346 | I12: =H12*$C12 -> 0.00014618994 | J12: =I12/I$47 -> 0.00055078094 | K12: =I12/F12*$B$2 -> 16.928759 | L12: =Processes!J9 -> 1.4535583 | M12: =L12*$C12 -> 0.00018799354 | N12: =M12/M$47 -> 0.00068858402 | P12: Electric charging - photovoltaic | T12: =F76 -> 0.26680557 | W12: Electric charging - photovoltaic | AA12: =I76 -> 0.017770438 | AD12: Electric charging - photovoltaic | AK12: =M76 -> 0.020308719 | AP12: 10000 | AQ12: =AQ$6+AE$9*$AP12 -> 8291.0169 | AR12: =AR$6+AG$10*$AP12 -> 10412.285 | AS12: =AS$6+AI$11*$AP12 -> 9335.8652 | AT12: =AT$6+AK$12*$AP12 -> 9501.3003 | AU12: =AU$6+AM$13*$AP12 -> 11921.57 | AW12: =AP12 -> 10000 | AX12: =AQ12/$AW12 -> 0.82910169 | AY12: =AR12/$AW12 -> 1.0412285 | AZ12: =AS12/$AW12 -> 0.93358652 | BA12: =AT12/$AW12 -> 0.95013003 | BB12: =AU12/$AW12 -> 1.192157
A13: ethylene glycol | B13: 5 | C13: =B13/$B$4 -> 3.3333333e-05 | D13: kg | E13: =Processes!H10 -> 49.878196 | F13: =E13*$C13 -> 0.0016626065 | G13: =F13/F$47 -> 0.0004176542 | H13: =Processes!G10 -> 1.2878908 | I13: =H13*$C13 -> 4.2929693e-05 | J13: =I13/I$47 -> 0.00016174066 | K13: =I13/F13*$B$2 -> 25.820717 | L13: =Processes!J10 -> 1.5171342 | M13: =L13*$C13 -> 5.057114e-05 | N13: =M13/M$47 -> 0.00018523232 | P13: Electric charging - hard coal | U13: =F77 -> 2.6881507 | W13: Electric charging - hard coal | AB13: =I77 -> 0.25785833 | AD13: Electric charging - hard coal | AM13: =M77 -> 0.26233566 | AP13: 20000 | AQ13: =AQ$6+AE$9*$AP13 -> 10612.028 | AR13: =AR$6+AG$10*$AP13 -> 11526.357 | AS13: =AS$6+AI$11*$AP13 -> 9373.5173 | AT13: =AT$6+AK$12*$AP13 -> 9704.3875 | AU13: =AU$6+AM$13*$AP13 -> 14544.926 | AW13: =AP13 -> 20000 | AX13: =AQ13/$AW13 -> 0.53060139 | AY13: =AR13/$AW13 -> 0.57631785 | AZ13: =AS13/$AW13 -> 0.46867586 | BA13: =AT13/$AW13 -> 0.48521937 | BB13: =AU13/$AW13 -> 0.72724631
A14: flat glass, uncoated | B14: 31.6 | C14: =B14/$B$4 -> 0.00021066667 | D14: kg | E14: =Processes!H11 -> 11.436901 | F14: =E14*$C14 -> 0.0024093738 | G14: =F14/F$47 -> 0.00060524548 | H14: =Processes!G11 -> 0.95946892 | I14: =H14*$C14 -> 0.00020212812 | J14: =I14/I$47 -> 0.00076153198 | K14: =I14/F14*$B$2 -> 83.892387 | L14: =Processes!J11 -> 1.0141071 | M14: =L14*$C14 -> 0.00021363856 | N14: =M14/M$47 -> 0.00078251678 | P14: Net value | Q14: =SUM(Q6:Q9) -> 3.9808208 | R14: =SUM(R6:R10) -> 2.9359837 | S14: =SUM(S6:S8, S11) -> 0.62893203 | T14: =SUM(T6:T8,T12) -> 0.8450214 | U14: =SUM(U6:U8,U13) -> 3.2663665 | W14: Net value | X14: =SUM(X6:X12) -> 0.26542302 | Y14: =SUM(Y6:Y12) -> 0.14064063 | Z14: =SUM(Z6:Z12) -> 0.039939452 | AA14: =SUM(AA6:AA12) -> 0.054375822 | AB14: =SUM(AB6:AB13) -> 0.29446371 | AD14: Net value | AE14: =SUM(AE6:AE9) -> 0.27301467 | AG14: =SUM(AG6:AG10) -> 0.15287203 | AI14: =SUM(AI6:AI8, AI11) -> 0.045230041 | AK14: =SUM(AK6:AK8, AK12) -> 0.061773553 | AM14: =SUM(AM6:AM8, AM13) -> 0.30380049 | AP14: 30000 | AQ14: =AQ$6+AE$9*$AP14 -> 12933.039 | AR14: =AR$6+AG$10*$AP14 -> 12640.429 | AS14: =AS$6+AI$11*$AP14 -> 9411.1693 | AT14: =AT$6+AK$12*$AP14 -> 9907.4747 | AU14: =AU$6+AM$13*$AP14 -> 17168.283 | AW14: =AP14 -> 30000 | AX14: =AQ14/$AW14 -> 0.43110129 | AY14: =AR14/$AW14 -> 0.42134763 | AZ14: =AS14/$AW14 -> 0.31370564 | BA14: =AT14/$AW14 -> 0.33024916 | BB14: =AU14/$AW14 -> 0.5722761
A15: heat, district or industrial, natural gas | B15: 2331 | C15: =B15/$B$4 -> 0.01554 | D15: MJ | E15: =Processes!H12 -> 0.66634297 | F15: =E15*$C15 -> 0.01035497 | G15: =F15/F$47 -> 0.0026012147 | H15: =Processes!G12 -> 0.033782061 | I15: =H15*$C15 -> 0.00052497323 | J15: =I15/I$47 -> 0.0019778738 | K15: =I15/F15*$B$2 -> 50.697708 | L15: =Processes!J12 -> 0.037879735 | M15: =L15*$C15 -> 0.00058865108 | N15: =M15/M$47 -> 0.0021561152 | AD15: Climate change, short term - Open LCA | AF15: 0.273011 | AH15: 0.14781 | AJ15: 0.031087 | AL15: 0.0395282 | AP15: 40000 | AQ15: =AQ$6+AE$9*$AP15 -> 15254.05 | AR15: =AR$6+AG$10*$AP15 -> 13754.501 | AS15: =AS$6+AI$11*$AP15 -> 9448.8214 | AT15: =AT$6+AK$12*$AP15 -> 10110.562 | AU15: =AU$6+AM$13*$AP15 -> 19791.639 | AW15: =AP15 -> 40000 | AX15: =AQ15/$AW15 -> 0.38135124 | AY15: =AR15/$AW15 -> 0.34386252 | AZ15: =AS15/$AW15 -> 0.23622053 | BA15: =AT15/$AW15 -> 0.25276405 | BB15: =AU15/$AW15 -> 0.49479099
A16: lead | B16: 13.7 | C16: =B16/$B$4 -> 9.1333333e-05 | D16: kg | E16: =Processes!H13 -> 16.66536 | F16: =E16*$C16 -> 0.0015221029 | G16: =F16/F$47 -> 0.00038235906 | H16: =Processes!G13 -> 1.2213615 | I16: =H16*$C16 -> 0.00011155102 | J16: =I16/I$47 -> 0.00042027634 | K16: =I16/F16*$B$2 -> 73.287434 | L16: =Processes!J13 -> 1.3573807 | M16: =L16*$C16 -> 0.0001239741 | N16: =M16/M$47 -> 0.00045409319 | AD16: from open LCA in kgCO2equ short per FU | AE16: =0.000000223314/0.000000083 -> 2.6905301 | AG16: =0.000000120897/0.000000083 -> 1.4565904 | AP16: 50000 | AQ16: =AQ$6+AE$9*$AP16 -> 17575.061 | AR16: =AR$6+AG$10*$AP16 -> 14868.573 | AS16: =AS$6+AI$11*$AP16 -> 9486.4735 | AT16: =AT$6+AK$12*$AP16 -> 10313.649 | AU16: =AU$6+AM$13*$AP16 -> 22414.996 | AW16: =AP16 -> 50000 | AX16: =AQ16/$AW16 -> 0.35150121 | AY16: =AR16/$AW16 -> 0.29737146 | AZ16: =AS16/$AW16 -> 0.18972947 | BA16: =AT16/$AW16 -> 0.20627298 | BB16: =AU16/$AW16 -> 0.44829992
A17: Light fuel oil, burned in furnace 1MW of greenhouse/MJ - RER | B17: 66.2 | C17: =B17/$B$4 -> 0.00044133333 | D17: MJ | E17: =Processes!H14 -> 1.28 | F17: =E17*$C17 -> 0.00056490667 | G17: =F17/F$47 -> 0.00014190708 | H17: =Processes!G14 -> 0.085 | I17: =H17*$C17 -> 3.7513333e-05 | J17: =I17/I$47 -> 0.00014133414 | K17: =I17/F17*$B$2 -> 66.40625 | L17: =Processes!J14 -> 0.08659 | M17: =L17*$C17 -> 3.8215053e-05 | N17: =M17/M$47 -> 0.00013997436 | U17: =0.024/0.065/55*100 -> 0.67132867 | AP17: 60000 | AQ17: =AQ$6+AE$9*$AP17 -> 19896.072 | AR17: =AR$6+AG$10*$AP17 -> 15982.645 | AS17: =AS$6+AI$11*$AP17 -> 9524.1255 | AT17: =AT$6+AK$12*$AP17 -> 10516.736 | AU17: =AU$6+AM$13*$AP17 -> 25038.353 | AW17: =AP17 -> 60000 | AX17: =AQ17/$AW17 -> 0.3316012 | AY17: =AR17/$AW17 -> 0.26637741 | AZ17: =AS17/$AW17 -> 0.15873543 | BA17: =AT17/$AW17 -> 0.17527894 | BB17: =AU17/$AW17 -> 0.41730588
A18: nickel, class 1 | B18: 1.5 | C18: =B18/$B$4 -> 1e-05 | D18: kg | E18: =Processes!H15 -> 275.14106 | F18: =E18*$C18 -> 0.0027514106 | G18: =F18/F$47 -> 0.00069116665 | H18: =Processes!G15 -> 14.802611 | I18: =H18*$C18 -> 0.00014802611 | J18: =I18/I$47 -> 0.00055769884 | K18: =I18/F18*$B$2 -> 53.80008 | L18: =Processes!J15 -> 18.711015 | M18: =L18*$C18 -> 0.00018711015 | N18: =M18/M$47 -> 0.00068534833 | AP18: 70000 | AQ18: =AQ$6+AE$9*$AP18 -> 22217.083 | AR18: =AR$6+AG$10*$AP18 -> 17096.717 | AS18: =AS$6+AI$11*$AP18 -> 9561.7776 | AT18: =AT$6+AK$12*$AP18 -> 10719.823 | AU18: =AU$6+AM$13*$AP18 -> 27661.709 | AW18: =AP18 -> 70000 | AX18: =AQ18/$AW18 -> 0.3173869 | AY18: =AR18/$AW18 -> 0.24423881 | AZ18: =AS18/$AW18 -> 0.13659682 | BA18: =AT18/$AW18 -> 0.15314033 | BB18: =AU18/$AW18 -> 0.39516727
A19: polyethylene, high density, granulate | B19: 107.1 | C19: =B19/$B$4 -> 0.000714 | D19: kg | E19: =Processes!H16 -> 79.357704 | F19: =E19*$C19 -> 0.056661401 | G19: =F19/F$47 -> 0.014233597 | H19: =Processes!G16 -> 1.9192517 | I19: =H19*$C19 -> 0.0013703457 | J19: =I19/I$47 -> 0.0051628744 | K19: =I19/F19*$B$2 -> 24.184819 | L19: =Processes!J16 -> 2.315399 | M19: =L19*$C19 -> 0.0016531949 | N19: =M19/M$47 -> 0.0060553335 | AP19: 80000 | AQ19: =AQ$6+AE$9*$AP19 -> 24538.094 | AR19: =AR$6+AG$10*$AP19 -> 18210.789 | AS19: =AS$6+AI$11*$AP19 -> 9599.4297 | AT19: =AT$6+AK$12*$AP19 -> 10922.911 | AU19: =AU$6+AM$13*$AP19 -> 30285.066 | AW19: =AP19 -> 80000 | AX19: =AQ19/$AW19 -> 0.30672617 | AY19: =AR19/$AW19 -> 0.22763486 | AZ19: =AS19/$AW19 -> 0.11999287 | BA19: =AT19/$AW19 -> 0.13653638 | BB19: =AU19/$AW19 -> 0.37856332
A20: polypropylene, granulate | B20: 51.4 | C20: =B20/$B$4 -> 0.00034266667 | D20: kg | E20: =Processes!H17 -> 77.070943 | F20: =E20*$C20 -> 0.026409643 | G20: =F20/F$47 -> 0.0066342205 | H20: =Processes!G17 -> 1.5167522 | I20: =H20*$C20 -> 0.00051974042 | J20: =I20/I$47 -> 0.0019581588 | K20: =I20/F20*$B$2 -> 19.679949 | L20: =Processes!J17 -> 1.9003221 | M20: =L20*$C20 -> 0.00065117704 | N20: =M20/M$47 -> 0.0023851357 | AP20: 90000 | AQ20: =AQ$6+AE$9*$AP20 -> 26859.105 | AR20: =AR$6+AG$10*$AP20 -> 19324.861 | AS20: =AS$6+AI$11*$AP20 -> 9637.0817 | AT20: =AT$6+AK$12*$AP20 -> 11125.998 | AU20: =AU$6+AM$13*$AP20 -> 32908.422 | AW20: =AP20 -> 90000 | AX20: =AQ20/$AW20 -> 0.2984345 | AY20: =AR20/$AW20 -> 0.21472067 | AZ20: =AS20/$AW20 -> 0.10707869 | BA20: =AT20/$AW20 -> 0.1236222 | BB20: =AU20/$AW20 -> 0.36564914
A21: polyvinylchloride, suspension polymerised | B21: 16.8 | C21: =B21/$B$4 -> 0.000112 | D21: kg | E21: =Processes!H18 -> 57.351667 | F21: =E21*$C21 -> 0.0064233867 | G21: =F21/F$47 -> 0.0016135835 | H21: =Processes!G18 -> 2.1136888 | I21: =H21*$C21 -> 0.00023673315 | J21: =I21/I$47 -> 0.00089190886 | K21: =I21/F21*$B$2 -> 36.85488 | L21: =Processes!J18 -> 2.4231058 | M21: =L21*$C21 -> 0.00027138785 | N21: =M21/M$47 -> 0.00099404126 | AP21: 100000 | AQ21: =AQ$6+AE$9*$AP21 -> 29180.116 | AR21: =AR$6+AG$10*$AP21 -> 20438.933 | AS21: =AS$6+AI$11*$AP21 -> 9674.7338 | AT21: =AT$6+AK$12*$AP21 -> 11329.085 | AU21: =AU$6+AM$13*$AP21 -> 35531.779 | AW21: =AP21 -> 100000 | AX21: =AQ21/$AW21 -> 0.29180116 | AY21: =AR21/$AW21 -> 0.20438933 | AZ21: =AS21/$AW21 -> 0.096747338 | BA21: =AT21/$AW21 -> 0.11329085 | BB21: =AU21/$AW21 -> 0.35531779
A22: section bar rolling, steel | B22: 213.2 | C22: =B22/$B$4 -> 0.0014213333 | D22: kg | E22: =Processes!H19 -> 1.5173103 | F22: =E22*$C22 -> 0.0021566037 | G22: =F22/F$47 -> 0.0005417485 | H22: =Processes!G19 -> 0.15973425 | I22: =H22*$C22 -> 0.00022703561 | J22: =I22/I$47 -> 0.00085537273 | K22: =I22/F22*$B$2 -> 105.27461 | L22: =Processes!J19 -> 0.17059246 | M22: =L22*$C22 -> 0.00024246875 | N22: =M22/M$47 -> 0.00088811618 | AP22: 110000 | AQ22: =AQ$6+AE$9*$AP22 -> 31501.126 | AR22: =AR$6+AG$10*$AP22 -> 21553.005 | AS22: =AS$6+AI$11*$AP22 -> 9712.3859 | AT22: =AT$6+AK$12*$AP22 -> 11532.172 | AU22: =AU$6+AM$13*$AP22 -> 38155.136 | AW22: =AP22 -> 110000 | AX22: =AQ22/$AW22 -> 0.28637388 | AY22: =AR22/$AW22 -> 0.1959364 | AZ22: =AS22/$AW22 -> 0.088294417 | BA22: =AT22/$AW22 -> 0.10483793 | BB22: =AU22/$AW22 -> 0.34686487
A23: sheet rolling, steel | B23: 568.1 | C23: =B23/$B$4 -> 0.0037873333 | D23: kg | E23: =Processes!H20 -> 4.9637527 | F23: =E23*$C23 -> 0.018799386 | G23: =F23/F$47 -> 0.0047224899 | H23: =Processes!G20 -> 0.2837106 | I23: =H23*$C23 -> 0.0010745066 | J23: =I23/I$47 -> 0.0040482796 | K23: =I23/F23*$B$2 -> 57.156474 | L23: =Processes!J20 -> 0.31869152 | M23: =L23*$C23 -> 0.001206991 | N23: =M23/M$47 -> 0.0044209749 | AP23: 120000 | AQ23: =AQ$6+AE$9*$AP23 -> 33822.137 | AR23: =AR$6+AG$10*$AP23 -> 22667.076 | AS23: =AS$6+AI$11*$AP23 -> 9750.038 | AT23: =AT$6+AK$12*$AP23 -> 11735.259 | AU23: =AU$6+AM$13*$AP23 -> 40778.492 | AW23: =AP23 -> 120000 | AX23: =AQ23/$AW23 -> 0.28185115 | AY23: =AR23/$AW23 -> 0.1888923 | AZ23: =AS23/$AW23 -> 0.081250316 | BA23: =AT23/$AW23 -> 0.097793828 | BB23: =AU23/$AW23 -> 0.33982077
A24: steel, low-alloyed, hot rolled | B24: 1039.5 | C24: =B24/$B$4 -> 0.00693 | D24: kg | E24: =Processes!H21 -> 25.220541 | F24: =E24*$C24 -> 0.17477835 | G24: =F24/F$47 -> 0.043905104 | H24: =Processes!G21 -> 1.9191216 | I24: =H24*$C24 -> 0.013299513 | J24: =I24/I$47 -> 0.050106854 | K24: =I24/F24*$B$2 -> 76.093594 | L24: =Processes!J21 -> 2.2139538 | M24: =L24*$C24 -> 0.0153427 | N24: =M24/M$47 -> 0.056197345 | AP24: 130000 | AQ24: =AQ$6+AE$9*$AP24 -> 36143.148 | AR24: =AR$6+AG$10*$AP24 -> 23781.148 | AS24: =AS$6+AI$11*$AP24 -> 9787.69 | AT24: =AT$6+AK$12*$AP24 -> 11938.347 | AU24: =AU$6+AM$13*$AP24 -> 43401.849 | AW24: =AP24 -> 130000 | AX24: =AQ24/$AW24 -> 0.27802422 | AY24: =AR24/$AW24 -> 0.18293191 | AZ24: =AS24/$AW24 -> 0.075289923 | BA24: =AT24/$AW24 -> 0.091833435 | BB24: =AU24/$AW24 -> 0.33386037
A25: platinum for catalytic converter | B25: 0.00168 | C25: =B25/$B$4 -> 1.12e-08 | D25: kg | E25: =Processes!H50 -> 1095329.2 | F25: =E25*$C25 -> 0.012267687 | G25: =F25/F$47 -> 0.0030816978 | H25: =Processes!G50 -> 63383.94 | I25: =H25*$C25 -> 0.00070990013 | J25: =I25/I$47 -> 0.0026745989 | K25: =I25/F25*$B$2 -> 57.867481 | L25: =Processes!J50 -> 69212.2 | M25: =L25*$C25 -> 0.00077517664 | N25: =M25/M$47 -> 0.0028393223 | AP25: 140000 | AQ25: =AQ$6+AE$9*$AP25 -> 38464.159 | AR25: =AR$6+AG$10*$AP25 -> 24895.22 | AS25: =AS$6+AI$11*$AP25 -> 9825.3421 | AT25: =AT$6+AK$12*$AP25 -> 12141.434 | AU25: =AU$6+AM$13*$AP25 -> 46025.205 | AW25: =AP25 -> 140000 | AX25: =AQ25/$AW25 -> 0.274744 | AY25: =AR25/$AW25 -> 0.177823 | AZ25: =AS25/$AW25 -> 0.070181015 | BA25: =AT25/$AW25 -> 0.086724527 | BB25: =AU25/$AW25 -> 0.32875147
A26: paladium for catalytic converter | B26: 0.000315 | C26: =B26/$B$4 -> 2.1e-09 | D26: kg | E26: =Processes!H52 -> 177394.83 | F26: =E26*$C26 -> 0.00037252913 | G26: =F26/F$47 -> 9.3580986e-05 | H26: =Processes!G52 -> 10203.118 | I26: =H26*$C26 -> 2.1426548e-05 | J26: =I26/I$47 -> 8.0726034e-05 | K26: =I26/F26*$B$2 -> 57.516435 | L26: =Processes!J52 -> 11194.083 | M26: =L26*$C26 -> 2.3507574e-05 | N26: =M26/M$47 -> 8.6103703e-05 | AP26: 150000 | AQ26: =AQ$6+AE$9*$AP26 -> 40785.17 | AR26: =AR$6+AG$10*$AP26 -> 26009.292 | AS26: =AS$6+AI$11*$AP26 -> 9862.9942 | AT26: =AT$6+AK$12*$AP26 -> 12344.521 | AU26: =AU$6+AM$13*$AP26 -> 48648.562 | AW26: =AP26 -> 150000 | AX26: =AQ26/$AW26 -> 0.27190114 | AY26: =AR26/$AW26 -> 0.17339528 | AZ26: =AS26/$AW26 -> 0.065753294 | BA26: =AT26/$AW26 -> 0.082296806 | BB26: =AU26/$AW26 -> 0.32432375
A27: sulfuric acid | B27: 0.84 | C27: =B27/$B$4 -> 5.6e-06 | D27: kg | E27: =Processes!H22 -> 3.2791276 | F27: =E27*$C27 -> 1.8363115e-05 | G27: =F27/F$47 -> 4.6128966e-06 | H27: =Processes!G22 -> 0.092734681 | I27: =H27*$C27 -> 5.1931421e-07 | J27: =I27/I$47 -> 1.956553e-06 | K27: =I27/F27*$B$2 -> 28.28029 | L27: =Processes!J22 -> 0.10553827 | M27: =L27*$C27 -> 5.9101431e-07 | N27: =M27/M$47 -> 2.1647712e-06 | AP27: 160000 | AQ27: =AQ$6+AE$9*$AP27 -> 43106.181 | AR27: =AR$6+AG$10*$AP27 -> 27123.364 | AS27: =AS$6+AI$11*$AP27 -> 9900.6462 | AT27: =AT$6+AK$12*$AP27 -> 12547.608 | AU27: =AU$6+AM$13*$AP27 -> 51271.918 | AW27: =AP27 -> 160000 | AX27: =AQ27/$AW27 -> 0.26941363 | AY27: =AR27/$AW27 -> 0.16952103 | AZ27: =AS27/$AW27 -> 0.061879039 | BA27: =AT27/$AW27 -> 0.078422551 | BB27: =AU27/$AW27 -> 0.32044949
A28: synthetic rubber | B28: 46.3 | C28: =B28/$B$4 -> 0.00030866667 | D28: kg | E28: =Processes!H23 -> 83.602397 | F28: =E28*$C28 -> 0.025805273 | G28: =F28/F$47 -> 0.0064824002 | H28: =Processes!G23 -> 2.4385405 | I28: =H28*$C28 -> 0.00075269617 | J28: =I28/I$47 -> 0.002835836 | K28: =I28/F28*$B$2 -> 29.168308 | L28: =Processes!J23 -> 2.727539 | M28: =L28*$C28 -> 0.00084190037 | N28: =M28/M$47 -> 0.0030837184 | AP28: 170000 | AQ28: =AQ$6+AE$9*$AP28 -> 45427.192 | AR28: =AR$6+AG$10*$AP28 -> 28237.436 | AS28: =AS$6+AI$11*$AP28 -> 9938.2983 | AT28: =AT$6+AK$12*$AP28 -> 12750.695 | AU28: =AU$6+AM$13*$AP28 -> 53895.275 | AW28: =AP28 -> 170000 | AX28: =AQ28/$AW28 -> 0.26721878 | AY28: =AR28/$AW28 -> 0.16610257 | AZ28: =AS28/$AW28 -> 0.058460578 | BA28: =AT28/$AW28 -> 0.07500409 | BB28: =AU28/$AW28 -> 0.31703103
A29: tap water | B29: 3381 | C29: =B29/$B$4 -> 0.02254 | D29: kg | E29: =Processes!H24 -> 0.0052467568 | F29: =E29*$C29 -> 0.0001182619 | G29: =F29/F$47 -> 2.9707918e-05 | H29: =Processes!G24 -> 0.00030655741 | I29: =H29*$C29 -> 6.909804e-06 | J29: =I29/I$47 -> 2.6033175e-05 | K29: =I29/F29*$B$2 -> 58.427981 | L29: =Processes!J24 -> 0.00033307439 | M29: =L29*$C29 -> 7.5074968e-06 | N29: =M29/M$47 -> 2.749851e-05 | AP29: 180000 | AQ29: =AQ$6+AE$9*$AP29 -> 47748.203 | AR29: =AR$6+AG$10*$AP29 -> 29351.508 | AS29: =AS$6+AI$11*$AP29 -> 9975.9504 | AT29: =AT$6+AK$12*$AP29 -> 12953.783 | AU29: =AU$6+AM$13*$AP29 -> 56518.632 | AW29: =AP29 -> 180000 | AX29: =AQ29/$AW29 -> 0.2652678 | AY29: =AR29/$AW29 -> 0.16306393 | AZ29: =AS29/$AW29 -> 0.055421946 | BA29: =AT29/$AW29 -> 0.071965458 | BB29: =AU29/$AW29 -> 0.3139924
A30: zinc | B30: 6.2 | C30: =B30/$B$4 -> 4.1333333e-05 | D30: kg | E30: =Processes!H25 -> 42.345437 | F30: =E30*$C30 -> 0.0017502781 | G30: =F30/F$47 -> 0.00043967769 | H30: =Processes!G25 -> 2.5227369 | I30: =H30*$C30 -> 0.00010427313 | J30: =I30/I$47 -> 0.00039285637 | K30: =I30/F30*$B$2 -> 59.575177 | L30: =Processes!J25 -> 2.7140714 | M30: =L30*$C30 -> 0.00011218162 | N30: =M30/M$47 -> 0.00041089959 | AP30: 190000 | AQ30: =AQ$6+AE$9*$AP30 -> 50069.214 | AR30: =AR$6+AG$10*$AP30 -> 30465.58 | AS30: =AS$6+AI$11*$AP30 -> 10013.602 | AT30: =AT$6+AK$12*$AP30 -> 13156.87 | AU30: =AU$6+AM$13*$AP30 -> 59141.988 | AW30: =AP30 -> 190000 | AX30: =AQ30/$AW30 -> 0.26352218 | AY30: =AR30/$AW30 -> 0.16034516 | AZ30: =AS30/$AW30 -> 0.052703171 | BA30: =AT30/$AW30 -> 0.069246683 | BB30: =AU30/$AW30 -> 0.31127362
A31: electricity, medium voltage | B31: 2247 | C31: =B31/$B$4 -> 0.01498 | D31: kWh | E31: =Processes!H46 -> 9.068338 | F31: =E31*$C31 -> 0.1358437 | G31: =F31/F$47 -> 0.034124546 | H31: =Processes!G46 -> 0.40013556 | I31: =H31*$C31 -> 0.0059940307 | J31: =I31/I$47 -> 0.022582934 | K31: =I31/F31*$B$2 -> 44.124464 | L31: =Processes!J46 -> 0.42848921 | M31: =L31*$C31 -> 0.0064187684 | N31: =M31/M$47 -> 0.023510708 | AP31: 200000 | AQ31: =AQ$6+AE$9*$AP31 -> 52390.225 | AR31: =AR$6+AG$10*$AP31 -> 31579.652 | AS31: =AS$6+AI$11*$AP31 -> 10051.255 | AT31: =AT$6+AK$12*$AP31 -> 13359.957 | AU31: =AU$6+AM$13*$AP31 -> 61765.345 | AW31: =AP31 -> 200000 | AX31: =AQ31/$AW31 -> 0.26195113 | AY31: =AR31/$AW31 -> 0.15789826 | AZ31: =AS31/$AW31 -> 0.050256273 | BA31: =AT31/$AW31 -> 0.066799784 | BB31: =AU31/$AW31 -> 0.30882672
A32: Transportation | B32: per vehicle | C32: per FU | AP32: 210000 | AQ32: =AQ$6+AE$9*$AP32 -> 54711.236 | AR32: =AR$6+AG$10*$AP32 -> 32693.724 | AS32: =AS$6+AI$11*$AP32 -> 10088.907 | AT32: =AT$6+AK$12*$AP32 -> 13563.044 | AU32: =AU$6+AM$13*$AP32 -> 64388.701 | AW32: =AP32 -> 210000 | AX32: =AQ32/$AW32 -> 0.2605297 | AY32: =AR32/$AW32 -> 0.1556844 | AZ32: =AS32/$AW32 -> 0.048042412 | BA32: =AT32/$AW32 -> 0.064585924 | BB32: =AU32/$AW32 -> 0.30661286
A33: transport, freight train | B33: 556.5 | C33: =B33/$B$4 -> 0.00371 | D33: t-km | E33: =Processes!H32 -> 0.7022219 | F33: =E33*$C33 -> 0.0026052433 | G33: =F33/F$47 -> 0.00065444877 | H33: =Processes!G32 -> 0.041812313 | I33: =H33*$C33 -> 0.00015512368 | J33: =I33/I$47 -> 0.00058443944 | K33: =I33/F33*$B$2 -> 59.542878 | L33: =Processes!J32 -> 0.044801749 | M33: =L33*$C33 -> 0.00016621449 | N33: =M33/M$47 -> 0.00060881156 | AP33: 220000 | AQ33: =AQ$6+AE$9*$AP33 -> 57032.247 | AR33: =AR$6+AG$10*$AP33 -> 33807.796 | AS33: =AS$6+AI$11*$AP33 -> 10126.559 | AT33: =AT$6+AK$12*$AP33 -> 13766.131 | AU33: =AU$6+AM$13*$AP33 -> 67012.058 | AW33: =AP33 -> 220000 | AX33: =AQ33/$AW33 -> 0.25923749 | AY33: =AR33/$AW33 -> 0.1536718 | AZ33: =AS33/$AW33 -> 0.046029812 | BA33: =AT33/$AW33 -> 0.062573324 | BB33: =AU33/$AW33 -> 0.30460026
A34: transport, freight, lorry 16-32 metric ton | B34: 59.1 | C34: =B34/$B$4 -> 0.000394 | D34: t-km | E34: =Processes!H33 -> 2.7131612 | F34: =E34*$C34 -> 0.0010689855 | G34: =F34/F$47 -> 0.00026853394 | H34: =Processes!G33 -> 0.16557683 | I34: =H34*$C34 -> 6.5237271e-05 | J34: =I34/I$47 -> 0.00024578603 | K34: =I34/F34*$B$2 -> 61.027274 | L34: =Processes!J33 -> 0.17185733 | M34: =L34*$C34 -> 6.7711788e-05 | N34: =M34/M$47 -> 0.0002480152 | AP34: 230000 | AQ34: =AQ$6+AE$9*$AP34 -> 59353.258 | AR34: =AR$6+AG$10*$AP34 -> 34921.868 | AS34: =AS$6+AI$11*$AP34 -> 10164.211 | AT34: =AT$6+AK$12*$AP34 -> 13969.218 | AU34: =AU$6+AM$13*$AP34 -> 69635.414 | AW34: =AP34 -> 230000 | AX34: =AQ34/$AW34 -> 0.25805764 | AY34: =AR34/$AW34 -> 0.15183421 | AZ34: =AS34/$AW34 -> 0.04419222 | BA34: =AT34/$AW34 -> 0.060735732 | BB34: =AU34/$AW34 -> 0.30276267
A35: transport, freight, sea, container ship | B35: 10400 | C35: =B35/$B$4 -> 0.069333333 | D35: t-km | E35: =Processes!H34 -> 0.12785666 | F35: =E35*$C35 -> 0.0088647284 | G35: =F35/F$47 -> 0.0022268595 | H35: =Processes!G34 -> 0.0090969942 | I35: =H35*$C35 -> 0.00063072493 | J35: =I35/I$47 -> 0.0023763008 | K35: =I35/F35*$B$2 -> 71.149944 | L35: =Processes!J34 -> 0.0094049824 | M35: =L35*$C35 -> 0.00065207878 | N35: =M35/M$47 -> 0.0023884386 | AP35: 240000 | AQ35: =AQ$6+AE$9*$AP35 -> 61674.269 | AR35: =AR$6+AG$10*$AP35 -> 36035.94 | AS35: =AS$6+AI$11*$AP35 -> 10201.863 | AT35: =AT$6+AK$12*$AP35 -> 14172.306 | AU35: =AU$6+AM$13*$AP35 -> 72258.771 | AW35: =AP35 -> 240000 | AX35: =AQ35/$AW35 -> 0.25697612 | AY35: =AR35/$AW35 -> 0.15014975 | AZ35: =AS35/$AW35 -> 0.042507762 | BA35: =AT35/$AW35 -> 0.059051273 | BB35: =AU35/$AW35 -> 0.30107821
A36: Use phase | B36: per V-km | C36: per FU | AP36: 250000 | AQ36: =AQ$6+AE$9*$AP36 -> 63995.28 | AR36: =AR$6+AG$10*$AP36 -> 37150.012 | AS36: =AS$6+AI$11*$AP36 -> 10239.515 | AT36: =AT$6+AK$12*$AP36 -> 14375.393 | AU36: =AU$6+AM$13*$AP36 -> 74882.128 | AW36: =AP36 -> 250000 | AX36: =AQ36/$AW36 -> 0.25598112 | AY36: =AR36/$AW36 -> 0.14860005 | AZ36: =AS36/$AW36 -> 0.040958059 | BA36: =AT36/$AW36 -> 0.057501571 | BB36: =AU36/$AW36 -> 0.29952851
A37: Supply chain petrol, low-sulfur | B37: 0.061904762 | C37: =B37 -> 0.061904762 | D37: kg | E37: =Processes!H45 -> 54.400731 | F37: =E37*$C37 -> 3.3676643 | G37: =F37/F$47 -> 0.84597235 | H37: =Processes!G45 -> 0.58292348 | I37: =H37*$C37 -> 0.036085739 | J37: =I37/I$47 -> 0.13595557 | K37: =I37/F37*$B$2 -> 10.715361 | L37: =Processes!J45 -> 0.63547923 | M37: =L37*$C37 -> 0.03933919 | N37: =M37/M$47 -> 0.14409185 | AP37: 260000 | AQ37: =AQ$6+AE$9*$AP37 -> 66316.291 | AR37: =AR$6+AG$10*$AP37 -> 38264.084 | AS37: =AS$6+AI$11*$AP37 -> 10277.167 | AT37: =AT$6+AK$12*$AP37 -> 14578.48 | AU37: =AU$6+AM$13*$AP37 -> 77505.484 | AW37: =AP37 -> 260000 | AX37: =AQ37/$AW37 -> 0.25506266 | AY37: =AR37/$AW37 -> 0.14716955 | AZ37: =AS37/$AW37 -> 0.039527565 | BA37: =AT37/$AW37 -> 0.056071077 | BB37: =AU37/$AW37 -> 0.29809802
A38: Direct combustion | B38: 0.061904762 | C38: =B38 -> 0.061904762 | D38: kg | E38: 0 | F38: =E38*$C38 -> 0 | G38: =F38/F$47 -> 0 | H38: =0.2024/0.065 -> 3.1138462 | I38: =H38*$C38 -> 0.1927619 | J38: =I38/I$47 -> 0.72624411 | K38: =I38/F37*$B$2 -> 57.23905 | L38: =0.2024/0.065 -> 3.1138462 | M38: =L38*$C38 -> 0.1927619 | N38: =M38/M$47 -> 0.70604961 | AP38: 270000 | AQ38: =AQ$6+AE$9*$AP38 -> 68637.302 | AR38: =AR$6+AG$10*$AP38 -> 39378.156 | AS38: =AS$6+AI$11*$AP38 -> 10314.819 | AT38: =AT$6+AK$12*$AP38 -> 14781.567 | AU38: =AU$6+AM$13*$AP38 -> 80128.841 | AW38: =AP38 -> 270000 | AX38: =AQ38/$AW38 -> 0.25421223 | AY38: =AR38/$AW38 -> 0.14584502 | AZ38: =AS38/$AW38 -> 0.038203033 | BA38: =AT38/$AW38 -> 0.054746545 | BB38: =AU38/$AW38 -> 0.29677348
A39: Disposal | B39: per vehicle over lifespan | C39: per FU | AP39: 280000 | AQ39: =AQ$6+AE$9*$AP39 -> 70958.313 | AR39: =AR$6+AG$10*$AP39 -> 40492.228 | AS39: =AS$6+AI$11*$AP39 -> 10352.471 | AT39: =AT$6+AK$12*$AP39 -> 14984.654 | AU39: =AU$6+AM$13*$AP39 -> 82752.197 | AW39: =AP39 -> 280000 | AX39: =AQ39/$AW39 -> 0.25342255 | AY39: =AR39/$AW39 -> 0.1446151 | AZ39: =AS39/$AW39 -> 0.036973111 | BA39: =AT39/$AW39 -> 0.053516623 | BB39: =AU39/$AW39 -> 0.29554356
A40: emulsion paint incineration | B40: =B7 -> 4.4 | C40: =B40/$B$4 -> 2.9333333e-05 | D40: kg | E40: =Processes!H35 -> 1.8340469 | F40: =E40*$C40 -> 5.3798708e-05 | G40: =F40/F$47 -> 1.3514476e-05 | H40: =Processes!G35 -> 1.1106367 | I40: =H40*$C40 -> 3.2578677e-05 | J40: =I40/I$47 -> 0.00012274247 | K40: =I40/F40*$B$2 -> 605.56615 | L40: =Processes!J35 -> 1.1236763 | M40: =L40*$C40 -> 3.2961171e-05 | N40: =M40/M$47 -> 0.0001207304 | AP40: 290000 | AQ40: =AQ$6+AE$9*$AP40 -> 73279.324 | AR40: =AR$6+AG$10*$AP40 -> 41606.3 | AS40: =AS$6+AI$11*$AP40 -> 10390.123 | AT40: =AT$6+AK$12*$AP40 -> 15187.742 | AU40: =AU$6+AM$13*$AP40 -> 85375.554 | AW40: =AP40 -> 290000 | AX40: =AQ40/$AW40 -> 0.25268732 | AY40: =AR40/$AW40 -> 0.14347 | AZ40: =AS40/$AW40 -> 0.035828011 | BA40: =AT40/$AW40 -> 0.052371523 | BB40: =AU40/$AW40 -> 0.29439846
A41: glass incineration | B41: =B14 -> 31.6 | C41: =B41/$B$4 -> 0.00021066667 | D41: kg | E41: =Processes!H36 -> 0.27058356 | F41: =E41*$C41 -> 5.7002936e-05 | G41: =F41/F$47 -> 1.4319393e-05 | H41: =Processes!G36 -> 0.011153419 | I41: =H41*$C41 -> 2.3496536e-06 | J41: =I41/I$47 -> 8.8524861e-06 | K41: =I41/F41*$B$2 -> 41.21987 | L41: =Processes!J36 -> 0.013427409 | M41: =L41*$C41 -> 2.8287075e-06 | N41: =M41/M$47 -> 1.0361009e-05 | AP41: 300000 | AQ41: =AQ$6+AE$9*$AP41 -> 75600.335 | AR41: =AR$6+AG$10*$AP41 -> 42720.372 | AS41: =AS$6+AI$11*$AP41 -> 10427.775 | AT41: =AT$6+AK$12*$AP41 -> 15390.829 | AU41: =AU$6+AM$13*$AP41 -> 87998.911 | AW41: =AP41 -> 300000 | AX41: =AQ41/$AW41 -> 0.25200112 | AY41: =AR41/$AW41 -> 0.14240124 | AZ41: =AS41/$AW41 -> 0.034759251 | BA41: =AT41/$AW41 -> 0.051302763 | BB41: =AU41/$AW41 -> 0.2933297
...

Sheet Life Cycle Costing petrol vs el
A3: Vehicle lifetime before resale | B3: 10
A4: Vehicle lifespan (km/vehicle) | B4: 150000 | F4: Costs | J4: Costs
A5: Transportation by Gas Vehicle FU= 1 vehicle km Life Cycle stage (150,000 km lifespan) | C5: Quantity original unit | D5: Quantity per FU | E5: Unit | F5: price/Unit [Euro/Unit] | G5: Cost per FU [Euro/V-km] | H5: fraction costs | J5: Euro/V-km | K5: Petrol Vehicle | L5: Electric Vehicle | M5: Leased electric vehicle
A6: Purchase | B6: Cost relevant distance | C6: per vehicle over lifespan | D6: per FU | J6: Purchase | K6: =SUM(G7:G8) -> 0.26666667 | L6: =SUM(G29:G30) -> 0.26666667 | M6: =SUM(G53:G54) -> 0.0088888889
A7: 1 vehicle incl. Taxes | B7: =$B$4 -> 150000 | C7: 1 | D7: =C7/B7 -> 6.6666667e-06 | E7: p | F7: 40000 | G7: =F7*D7 -> 0.26666667 | H7: =G7/G$20 -> 0.56151001 | J7: Fixed annual costs | K7: =SUM(G10:G11) -> 0.046666667 | L7: =SUM(G32:G33) -> 0.035555556 | M7: =SUM(G56:G58) -> 0.39555556
A8: Tax on vehicle at purchase | B8: =$B$4 -> 150000 | C8: 1 | D8: =C8/B8 -> 6.6666667e-06 | E8: p | G8: =F8*D8 -> 0 | H8: =G8/G$20 -> 0 | J8: Variable cost maintenance | K8: =SUM(G13:G14) -> 0.105 | L8: =SUM(G35:G36) -> 0.06 | M8: =SUM(G60:G61) -> 0
A9: Fixed annual costs | B9: km/yr | C9: per year | D9: per FU | J9: Variable cost Fuel - Use phase | K9: =G16 -> 0.076576577 | L9: =G38 -> 0.13 | M9: =SUM(G63) -> 0.13
A10: Insurance per year | B10: 15000 | C10: 1 | D10: =C10/B10 -> 6.6666667e-05 | E10: p | F10: 500 | G10: =F10*$D10 -> 0.033333333 | H10: =G10/G$20 -> 0.070188751 | J10: Resale | K10: =G18 -> -0.02 | L10: =G40 -> -0.013333333 | M10: =G65 -> 0
A11: Registration taxes per year | B11: =B4/B3 -> 15000 | C11: 1 | D11: =C11/B11 -> 6.6666667e-05 | E11: p | F11: 200 | G11: =F11*$D11 -> 0.013333333 | H11: =G11/G$20 -> 0.0280755 | J11: Total | K11: =SUM(K6:K10) -> 0.47490991 | L11: =SUM(L6:L10) -> 0.47888889 | M11: =SUM(M6:M10) -> 0.53444444
A12: Variabl cost maintenance | B12: km until change | D12: per FU
A13: maintenance per 10000km | B13: 10000 | C13: 1 | D13: =C13/B13 -> 0.0001 | E13: p | F13: 750 | G13: =F13*$D13 -> 0.075 | H13: =G13/G$20 -> 0.15792469
A14: Tires change every 20000 km | B14: 20000 | C14: 4 | D14: =C14/B14 -> 0.0002 | E14: p | F14: 150 | G14: =F14*$D14 -> 0.03 | H14: =G14/G$20 -> 0.063169876
A15: Variable cost Fuel - Use phase | B15: liter | C15: per V-km | D15: per FU
A16: Supply chain petrol, low-sulfur | B16: 1 | C16: =1/22.2 -> 0.045045045 | D16: =C16/B16 -> 0.045045045 | E16: L | F16: 1.7 | G16: =F16*$D16 -> 0.076576577 | H16: =G16/G$20 -> 0.16124443
A17: Resale value - end of life | C17: per vehicle over lifespan | D17: per FU
A18: 1 vehicle | B18: =$B$4 -> 150000 | C18: -1 | D18: =C18/B18 -> -6.6666667e-06 | E18: p | F18: 3000 | G18: =F18*$D18 -> -0.02 | H18: =G18/G$20 -> -0.04211325
A19: Total | D19: per FU
A20: Total | C20: - | E20: - | G20: =SUM(G7:G18) -> 0.47490991 | H20: =G20/G$20 -> 1
H21: =SUM(H7:H17) -> 1.0421133
A25: Vehicle lifetime before resale | B25: 10
A26: Vehicle lifespan (km/vehicle) | B26: 225000 | F26: Costs
A27: Transportation by Electric Vehicle FU= 1 vehicle km Life Cycle stage (x km lifespan) | C27: Quantity original unit | D27: Quantity per FU | E27: Unit | F27: price/Unit [Euro/Unit] | G27: Cost per FU [Euro/V-km] | H27: fraction costs
A28: Purchase | B28: Cost relevant distance | C28: per vehicle over lifespan | D28: per FU
A29: 1 vehicle | B29: =$B$26 -> 225000 | C29: 1 | D29: =C29/B29 -> 4.4444444e-06 | E29: p | F29: 60000 | G29: =F29*D29 -> 0.26666667 | H29: =G29/G$42 -> 0.55684455
A30: Tax on vehicle at purchase | B30: =$B$26 -> 225000 | C30: 1 | D30: =C30/B30 -> 4.4444444e-06 | E30: p | G30: =F30*D30 -> 0 | H30: =G30/G$42 -> 0
A31: Fixed annual costs | C31: annual purchase | D31: per FU
A32: Insurance per year | B32: 22500 | C32: 1 | D32: =C32/B32 -> 4.4444444e-05 | E32: p | F32: 700 | G32: =F32*$D32 -> 0.031111111 | H32: =G32/G$42 -> 0.064965197
A33: Taxes for immatriculation per year | B33: 22500 | C33: 1 | D33: =C33/B33 -> 4.4444444e-05 | E33: p | F33: 100 | G33: =F33*$D33 -> 0.0044444444 | H33: =G33/G$42 -> 0.0092807425
A34: Variable cost maintenance | D34: per FU
A35: maintenance per 10000km | B35: 10000 | C35: 1 | D35: =C35/B35 -> 0.0001 | E35: p | F35: 300 | G35: =F35*$D35 -> 0.03 | H35: =G35/G$42 -> 0.062645012
A36: Tires change every 20000 km | B36: 20000 | C36: 4 | D36: =C36/B36 -> 0.0002 | E36: p | F36: 150 | G36: =F36*$D36 -> 0.03 | H36: =G36/G$42 -> 0.062645012
A37: Variable cost Fuel - Use phase | C37: per V-km | D37: per FU
A38: electricity | B38: 1 | C38: 0.26 | D38: =C38/B38 -> 0.26 | E38: kWh | F38: 0.5 | G38: =F38*$D38 -> 0.13 | H38: =G38/G$42 -> 0.27146172
A39: Resale value - end of life | C39: per vehicle over lifespan | D39: per FU
A40: 1 vehicle | B40: =$B$26 -> 225000 | C40: -1 | D40: =C40/B40 -> -4.4444444e-06 | E40: p | F40: 3000 | G40: =F40*$D40 -> -0.013333333 | H40: =G40/G$42 -> -0.027842227
A41: Total | D41: per FU
A42: Total | C42: - | E42: - | G42: =SUM(G29:G40) -> 0.47888889 | H42: =G42/G$42 -> 1
H43: =SUM(H29:H39) -> 1.0278422
A49: Vehicle lifetime before resale | B49: 10
A50: Vehicle lifespan (km/vehicle) | B50: 225000 | F50: Costs
...

Sheet Processes
B1: conversion kg_to_g | C1: 1000 | D1: g/kg | F1: Category | G1: air | H1: fossil+nuclear+primary forest | I1: CO2 fossil/total non renewable energy | J1: climate change
F2: Indicator | G2: CO2, fossil | H2: non-renewable energy resources | I2: Check combustion included | J2: GWP 100a | K2: renewable energy resources, total | L2: Non-renewable + renewable energy resources, total
B3: Activity Name | C3: Geography | D3: Reference Product Name | E3: Reference Product Unit | F3: Reference Product Amount | G3: kg | H3: MJ-Eq | I3: gCO2/MJ | J3: kg CO2-Eq | K3: MJ-Eq | L3: MJ-Eq
A4: 258 | B4: alkyd paint production, white, solvent-based, product in 60% solution state | C4: RER | D4: alkyd paint, white, without solvent, in 60% solution state | E4: kg | F4: 1 | G4: 4.8913828 | H4: 61.912708 | I4: =G4/H4*$C$1 -> 79.004505 | J4: 5.4372182 | K4: 20.945152 | L4: =K4+H4 -> 82.85786 | M4: Manufacturing (Materials + Processing)
A5: 470 | B5: aluminium production, primary, ingot | C5: RoW | D5: aluminium, primary, ingot | E5: kg | F5: 1 | G5: 19.24884 | H5: 218.89578 | I5: =G5/H5*$C$1 -> 87.936096 | J5: 20.97429 | K5: 3.5108374 | L5: =K5+H5 -> 222.40661
A6: 2017 | B6: chromium oxide production, flakes | C6: RoW | D6: chromium oxide, flakes | E6: kg | F6: 1 | G6: 5.6316443 | H6: 56.396524 | I6: =G6/H6*$C$1 -> 99.858004 | J6: 6.0199005 | K6: 4.4209444 | L6: =K6+H6 -> 60.817468
A7: 2582 | B7: market for copper, anode | C7: GLO | D7: copper, anode | E7: kg | F7: 1 | G7: 5.1792783 | H7: 74.579203 | I7: =G7/H7*$C$1 -> 69.446684 | J7: 5.8649728 | K7: 21.952496 | L7: =K7+H7 -> 96.531699
A8: 6808 | B8: electronics production, for control units | C8: RER | D8: electronics, for control units | E8: kg | F8: 1 | G8: 27.933745 | H8: 448.24729 | I8: =G8/H8*$C$1 -> 62.31771 | J8: 31.49787 | K8: 48.643082 | L8: =K8+H8 -> 496.89038
A9: 7031 | B9: ethylene production, average | C9: RER | D9: ethylene | E9: kg | F9: 1 | G9: 1.1303346 | H9: 66.770079 | I9: =G9/H9*$C$1 -> 16.928759 | J9: 1.4535583 | K9: 0.20028773 | L9: =K9+H9 -> 66.970366
A10: 7049 | B10: ethylene glycol production | C10: RER | D10: ethylene glycol | E10: kg | F10: 1 | G10: 1.2878908 | H10: 49.878196 | I10: =G10/H10*$C$1 -> 25.820717 | J10: 1.5171342 | K10: 2.0183654 | L10: =K10+H10 -> 51.896562
A11: 7381 | B11: market for flat glass, uncoated | C11: RoW | D11: flat glass, uncoated | E11: kg | F11: 1 | G11: 0.95946892 | H11: 11.436901 | I11: =G11/H11*$C$1 -> 83.892387 | J11: 1.0141071 | K11: 0.48573863 | L11: =K11+H11 -> 11.92264
A12: 8465 | B12: market for heat, district or industrial, natural gas | C12: RoW | D12: heat, district or industrial, natural gas | E12: MJ | F12: 1 | G12: 0.033782061 | H12: 0.66634297 | I12: =G12/H12*$C$1 -> 50.697708 | J12: 0.037879735 | K12: 0.0011740067 | L12: =K12+H12 -> 0.66751698
A13: 10999 | B13: market for lead | C13: GLO | D13: lead | E13: kg | F13: 1 | G13: 1.2213615 | H13: 16.66536 | I13: =G13/H13*$C$1 -> 73.287434 | J13: 1.3573807 | K13: 1.8267347 | L13: =K13+H13 -> 18.492095
A14: 1601 | B14: light fuel oil, burned in industrial furnace 1MW, non-modulating | C14: RER | D14: Light fuel oil, burned in furnace 1MW of greenhouse/MJ | E14: MJ | F14: 1 | G14: 0.085 | H14: 1.28 | I14: =G14/H14*$C$1 -> 66.40625 | J14: 0.08659 | K14: 0 | L14: =K14+H14 -> 1.28 | M14: *
A15: 12292 | B15: market for nickel, class 1 | C15: GLO | D15: nickel, class 1 | E15: kg | F15: 1 | G15: 14.802611 | H15: 275.14106 | I15: =G15/H15*$C$1 -> 53.80008 | J15: 18.711015 | K15: 221.99156 | L15: =K15+H15 -> 497.13262
A16: 13492 | B16: market for polyethylene, high density, granulate | C16: GLO | D16: polyethylene, high density, granulate | E16: kg | F16: 1 | G16: 1.9192517 | H16: 79.357704 | I16: =G16/H16*$C$1 -> 24.184819 | J16: 2.315399 | K16: 1.0089541 | L16: =K16+H16 -> 80.366658
A17: 13532 | B17: polypropylene production, granulate | C17: RER | D17: polypropylene, granulate | E17: kg | F17: 1 | G17: 1.5167522 | H17: 77.070943 | I17: =G17/H17*$C$1 -> 19.679949 | J17: 1.9003221 | K17: 1.0000909 | L17: =K17+H17 -> 78.071034
A18: 13598 | B18: market for polyvinylchloride, suspension polymerised | C18: GLO | D18: polyvinylchloride, suspension polymerised | E18: kg | F18: 1 | G18: 2.1136888 | H18: 57.351667 | I18: =G18/H18*$C$1 -> 36.85488 | J18: 2.4231058 | K18: 2.0070346 | L18: =K18+H18 -> 59.358701
A19: 14863 | B19: section bar rolling, steel | C19: RER | D19: section bar rolling, steel | E19: kg | F19: 1 | G19: 0.15973425 | H19: 1.5173103 | I19: =G19/H19*$C$1 -> 105.27461 | J19: 0.17059246 | K19: 0.25557595 | L19: =K19+H19 -> 1.7728863
A20: 15028 | B20: sheet rolling, steel | C20: RER | D20: sheet rolling, steel | E20: kg | F20: 1 | G20: 0.2837106 | H20: 4.9637527 | I20: =G20/H20*$C$1 -> 57.156474 | J20: 0.31869152 | K20: 0.42848881 | L20: =K20+H20 -> 5.3922415
A21: 15688 | B21: steel production, low-alloyed, hot rolled | C21: RER | D21: steel, low-alloyed, hot rolled | E21: kg | F21: 1 | G21: 1.9191216 | H21: 25.220541 | I21: =G21/H21*$C$1 -> 76.093594 | J21: 2.2139538 | K21: 2.1640414 | L21: =K21+H21 -> 27.384582
A22: 15998 | B22: market for sulfuric acid | C22: RER | D22: sulfuric acid | E22: kg | F22: 1 | G22: 0.092734681 | H22: 3.2791276 | I22: =G22/H22*$C$1 -> 28.28029 | J22: 0.10553827 | K22: 0.17320108 | L22: =K22+H22 -> 3.4523287
A23: 16111 | B23: market for synthetic rubber | C23: GLO | D23: synthetic rubber | E23: kg | F23: 1 | G23: 2.4385405 | H23: 83.602397 | I23: =G23/H23*$C$1 -> 29.168308 | J23: 2.727539 | K23: 3.1167715 | L23: =K23+H23 -> 86.719169
A24: 16201 | B24: tap water production, conventional treatment | C24: RoW | D24: tap water | E24: kg | F24: 1 | G24: 0.00030655741 | H24: 0.0052467568 | I24: =G24/H24*$C$1 -> 58.427981 | J24: 0.00033307439 | K24: 0.00055172447 | L24: =K24+H24 -> 0.0057984813
A25: 19516 | B25: market for zinc | C25: GLO | D25: zinc | E25: kg | F25: 1 | G25: 2.5227369 | H25: 42.345437 | I25: =G25/H25*$C$1 -> 59.575177 | J25: 2.7140714 | K25: 5.6209015 | L25: =K25+H25 -> 47.966339
A26: 981 | B26: battery production, Li-ion, rechargeable, prismatic | C26: GLO | D26: battery, Li-ion, rechargeable, prismatic | E26: kg | F26: 1 | G26: 7.0482569 | H26: 114.5666 | I26: =G26/H26*$C$1 -> 61.521042 | J26: 8.1666348 | K26: 14.109314 | L26: =K26+H26 -> 128.67592
... A30: 11694 | B30: metal working, average for steel product manufacturing | C30: RER | D30: metal working, average for steel product manufacturing | E30: kg | F30: 1 | G30: 1.4794537 | H30: 25.190272 | I30: =G30/H30*$C$1 -> 58.731151 | J30: 1.6605252 | K30: 2.8583433 | L30: =K30+H30 -> 28.048616
A31: 13590 | B31: market for polyurethane, rigid foam | C31: RoW | D31: polyurethane, rigid foam | E31: kg | F31: 1 | G31: 4.9718328 | H31: 121.66776 | I31: =G31/H31*$C$1 -> 40.864012 | J31: 6.4054308 | K31: 5.6740801 | L31: =K31+H31 -> 127.34184 | M31: Transport
A32: 16525 | B32: market group for transport, freight train | C32: RER | D32: transport, freight train | E32: metric ton*km | F32: 1 | G32: 0.041812313 | H32: 0.7022219 | I32: =G32/H32*$C$1 -> 59.542878 | J32: 0.044801749 | K32: 0.069494112 | L32: =K32+H32 -> 0.77171602
A33: 16629 | B33: market for transport, freight, lorry 16-32 metric ton, EURO4 | C33: RoW | D33: transport, freight, lorry 16-32 metric ton, EURO4 | E33: metric ton*km | F33: 1 | G33: 0.16557683 | H33: 2.7131612 | I33: =G33/H33*$C$1 -> 61.027274 | J33: 0.17185733 | K33: 0.029431245 | L33: =K33+H33 -> 2.7425924
A34: 16822 | B34: transport, freight, sea, container ship | C34: GLO | D34: transport, freight, sea, container ship | E34: metric ton*km | F34: 1 | G34: 0.0090969942 | H34: 0.12785666 | I34: =G34/H34*$C$1 -> 71.149944 | J34: 0.0094049824 | K34: 0.0008126868 | L34: =K34+H34 -> 0.12866935 | M34: Disposal
A35: 17771 | B35: treatment of waste emulsion paint, municipal incineration | C35: CH | D35: waste emulsion paint | E35: kg | F35: -1 | G35: 1.1106367 | H35: 1.8340469 | I35: =G35/H35*$C$1 -> 605.56615 | J35: 1.1236763 | K35: 0.18518093 | L35: =K35+H35 -> 2.0192278
A36: 17853 | B36: treatment of waste glass, municipal incineration | C36: CH | D36: waste glass | E36: kg | F36: -1 | G36: 0.011153419 | H36: 0.27058356 | I36: =G36/H36*$C$1 -> 41.21987 | J36: 0.013427409 | K36: 0.0070785741 | L36: =K36+H36 -> 0.27766213
A37: 18250 | B37: treatment of waste plastic, mixture, municipal incineration | C37: CH | D37: waste plastic, mixture | E37: kg | F37: -1 | G37: 2.3345751 | H37: 0.48331973 | I37: =G37/H37*$C$1 -> 4830.2913 | J37: 2.3458359 | K37: 0.041879641 | L37: =K37+H37 -> 0.52519938
A38: 19537 | B38: treatment of zinc in car shredder residue, municipal incineration | C38: CH | D38: zinc in car shredder residue | E38: kg | F38: -1 | G38: 0.22211976 | H38: 1.6770814 | I38: =G38/H38*$C$1 -> 132.44424 | J38: 0.23252513 | K38: 0.17878617 | L38: =K38+H38 -> 1.8558675
A39: 493 | B39: treatment of aluminium scrap, post-consumer, prepared for recycling, at remelter | C39: RoW | D39: aluminium, wrought alloy | E39: kg | F39: 1 | G39: 0.72918765 | H39: 9.0213324 | I39: =G39/H39*$C$1 -> 80.829263 | J39: 0.7999219 | K39: 1.2981548 | L39: =K39+H39 -> 10.319487
A40: 9875 | B40: treatment of metal scrap, mixed, for recycling, unsorted, sorting | C40: RoW | D40: iron scrap, sorted, pressed | E40: kg | F40: 1 | G40: 0.051301317 | H40: 0.72900092 | I40: =G40/H40*$C$1 -> 70.372088 | J40: 0.089742351 | K40: 0.033602192 | L40: =K40+H40 -> 0.76260311
A41: 17851 | B41: treatment of waste glass, inert material landfill | C41: CH | D41: waste glass | E41: kg | F41: -1 | G41: 0.003980719 | H41: 0.14588608 | I41: =G41/H41*$C$1 -> 27.28649 | J41: 0.0042370221 | K41: 0.0027956914 | L41: =K41+H41 -> 0.14868177
A42: 17961 | B42: treatment of waste mineral oil, hazardous waste incineration | C42: CH | D42: waste mineral oil | E42: kg | F42: -1 | G42: 2.8409763 | H42: 0.24716555 | I42: =G42/H42*$C$1 -> 11494.225 | J42: 2.8430456 | K42: 0.013825209 | L42: =K42+H42 -> 0.26099076
A43: 18257 | B43: treatment of waste plastic, mixture, sanitary landfill | C43: CH | D43: waste plastic, mixture | E43: kg | F43: -1 | G43: 0.024003382 | H43: 0.23960025 | I43: =G43/H43*$C$1 -> 100.18095 | J43: 0.096838258 | K43: 0.011725444 | L43: =K43+H43 -> 0.2513257
...

Sheet Midpoint results
B2: Impact world+ results midpoint
B3: Indicator | C3: Unit | D3: Gas | E3: Electric | F3: Photovoltaic | G3: Wind
B4: Climate change, long term | C4: kg CO2 eq (long) | D4: 0.26828 | E4: 0.141558 | F4: 0.0367715 | G4: 0.0288164
B5: Climate change, short term | C5: kg CO2 eq (short) | D5: 0.273011 | E5: 0.14781 | F5: 0.0395282 | G5: 0.031087
B6: Fossil and nuclear energy use | C6: MJ deprived | D6: 4.00116 | E6: 2.42259 | F6: 0.414244 | G6: 0.348267
B7: Freshwater acidification | C7: kg SO2 eq | D7: 4.84066e-15 | E7: 5.56387e-15 | F7: 1.87256e-15 | G7: 1.58225e-15
B8: Freshwater ecotoxicity | C8: CTUe | D8: 1720.69 | E8: 12579.5 | F8: 11990.5 | G8: 11541
B9: Freshwater eutrophication | C9: kg PO4 P-lim eq | D9: 2.97925e-06 | E9: 2.52043e-07 | F9: 2.34394e-07 | G9: 1.82202e-07
B10: Human toxicity cancer | C10: CTUh | D10: 2.15028e-08 | E10: 2.62793e-08 | F10: 1.60912e-08 | G10: 1.54138e-08
B11: Human toxicity non cancer | C11: CTUh | D11: 2.96036e-08 | E11: 7.97366e-08 | F11: 5.80477e-08 | G11: 5.41915e-08
B12: Ionizing radiations | C12: Bq C-14 eq | D12: 1.94129 | E12: 6.70424 | F12: 0.488585 | G12: 0.41063
B13: Land occupation, biodiversity | C13: m2 arable land eq .yr | D13: 0.0123922 | E13: 0.000740493 | F13: 0.000397184 | G13: 0.000383411
B14: Land transformation, biodiversity | C14: m2 arable land eq | D14: 5.6085e-05 | E14: 1.0287e-05 | F14: 5.5964e-06 | G14: 4.90069e-06
B15: Marine eutrophication | C15: kg N N-lim eq | D15: 1.05749e-05 | E15: 3.46873e-05 | F15: 2.85727e-05 | G15: 2.75701e-05
... B21: Water scarcity | C21: m3 world-eq | D21: 0.932842 | E21: 0.0474642 | F21: 0.0204532 | G21: 0.0116672

Sheet Input for Students
A1: kg/t conversion factor | B1: 1000
A2: g/kg | B2: 1000
A4: Transportation by Gas Vehicle | B4: Reference Product Name | C4: Reference Product Unit
A5: Manufacturing (Materials + Processing) | H5: steel, low-alloyed, hot rolled | I5: =B23 -> 1039.5 | J5: 1040 | K5: kg
A6: alkyd paint, white, without solvent, in 60% solution state | B6: 4.368 | C6: kg | D6: 4.16 | E6: =B6/D6 -> 1.05 | G6: alkyd paint, white, without solvent, in 60% solution state | H6: sheet rolling, steel | I6: =B22+B21 -> 781.2 | J6: 780 | K6: kg
A7: aluminium, primary, ingot | B7: 54.39 | C7: kg | D7: 51.8 | E7: =B7/D7 -> 1.05 | G7: aluminium, primary, ingot | H7: aluminium, primary, ingot | I7: =B7 -> 54.39 | J7: 55 | K7: kg
A8: chromium oxide, flakes | B8: 2.52 | C8: kg | D8: 2.4 | E8: =B8/D8 -> 1.05 | F8: Should not be chromium oxide | G8: chromium oxide, flakes | H8: other metals (Cu, Zn, Ni, Pb) | I8: =B8+B9+B10+B28+B17 -> 37.50075 | J8: 38 | K8: kg
A9: sheet rolling, copper | B9: 21.21 | C9: kg | D9: 20.2 | E9: =B9/D9 -> 1.05 | G9: sheet rolling, copper | H9: platinum | I9: =B24 -> 0.00168 | J9: 0.0017 | K9: kg
A10: electronics, for control units | B10: 6.11625 | C10: kg | D10: =B10/1.05 -> 5.825 | E10: =B10/D10 -> 1.05 | F10: Should not be chromium oxide | G10: electronics, for control units | H10: polyethylene, polypropylene & PVC | I10: =B18+B19+B20 -> 175.35 | J10: 175 | K10: kg
A11: ethylene | B11: 19.425 | C11: kg | D11: 18.5 | E11: =B11/D11 -> 1.05 | G11: ethylene | H11: synthetic rubber | I11: =B26 -> 46.305 | J11: 46 | K11: kg
A12: ethylene glycol | B12: 5.04 | C12: kg | D12: 4.8 | E12: =B12/D12 -> 1.05 | G12: ethylene glycol | H12: glas | I12: =B13 -> 31.605 | J12: 32 | K12: kg
A13: flat glass, uncoated | B13: 31.605 | C13: kg | D13: 30.1 | E13: =B13/D13 -> 1.05 | G13: flat glass, uncoated | H13: electronics, for control units | I13: =B10 -> 6.11625 | J13: 6.1 | K13: kg
A14: heat, district or industrial, natural gas | B14: 2331 | C14: MJ | D14: 2220 | E14: =B14/D14 -> 1.05 | G14: heat, district or industrial, natural gas | H14: ethylene, paints, fluids | I14: =B11+B6+B12+B25 -> 29.673 | J14: 30 | K14: kg
A15: lead | B15: 13.65 | C15: kg | D15: 13 | E15: =B15/D15 -> 1.05 | G15: lead | H15: tap water | I15: =B27 -> 3381 | J15: 3400 | K15: kg
A16: Light fuel oil, burned in furnace 1MW of greenhouse/MJ - RER | B16: 66.15 | C16: MJ | D16: 63 | E16: =B16/D16 -> 1.05 | G16: Light fuel oil, burned in furnace 1MW of greenhouse/MJ - RER | H16: heat, district or industrial, natural gas | I16: =B14+B16 -> 2397.15 | J16: 2400 | K16: MJ
A17: nickel, class 1 | B17: 1.47 | C17: kg | D17: 1.4 | E17: =B17/D17 -> 1.05 | G17: nickel, class 1 | H17: electricity, medium voltage | I17: =B29 -> 2247 | J17: 2250 | K17: kWh
A18: polyethylene, high density, granulate | B18: 107.1 | C18: kg | D18: 102 | E18: =B18/D18 -> 1.05 | G18: polyethylene, polypropylene & PVC
A19: polypropylene, granulate | B19: 51.45 | C19: kg | D19: 49 | E19: =B19/D19 -> 1.05 | G19: polypropylene, granulate
A20: polyvinylchloride, suspension polymerised | B20: 16.8 | C20: kg | D20: 16 | E20: =B20/D20 -> 1.05 | G20: polyvinylchloride, suspension polymerised
A21: section bar rolling, steel | B21: 213.15 | C21: kg | D21: 203 | E21: =B21/D21 -> 1.05 | G21: section bar rolling, steel | H21: v
A22: sheet rolling, steel | B22: 568.05 | C22: kg | D22: 541 | E22: =B22/D22 -> 1.05 | G22: sheet rolling, steel
A23: steel, low-alloyed, hot rolled | B23: 1039.5 | C23: kg | D23: =891+99 -> 990 | E23: =B23/D23 -> 1.05 | G23: steel, low-alloyed, hot rolled
A24: platinum | B24: =1.05*D24 -> 0.00168 | D24: 0.0016 | E24: =B24/D24 -> 1.05 | F24: Worth adding, not negligble | G24: platinum
A25: sulfuric acid | B25: 0.84 | C25: kg | D25: 0.8 | E25: =B25/D25 -> 1.05 | G25: sulfuric acid
A26: synthetic rubber | B26: 46.305 | C26: kg | D26: 44.1 | E26: =B26/D26 -> 1.05 | G26: synthetic rubber
A27: tap water | B27: 3381 | C27: kg | D27: 3220 | E27: =B27/D27 -> 1.05 | G27: tap water
A28: zinc | B28: 6.1845 | C28: kg | D28: 5.89 | E28: =B28/D28 -> 1.05 | G28: zinc | H28: x
A29: electricity, medium voltage | B29: =D29*1.05 -> 2247 | C29: kWh | D29: 2140 | E29: =B29/D29 -> 1.05 | F29: Electricity was directly in kWh, do not divide by 3.6 | G29: electricity, medium voltage
A30: Transportation *Please see note in top-corner* | B30: =SUM(B6:B29) -> 10234.325 | D30: =SUM(D6:D29) -> 9746.9766 | I30: =SUM(I6:I28) -> 9187.2917
A31: transport, freight train | B31: 0.00371 | C31: t-km | D31: 530 | E31: =B31*150000/D31 -> 1.05
A32: transport, freight, lorry 16-32 metric ton | B32: 0.00039382 | C32: t-km | D32: 53 | E32: =B32*150000/D32 -> 1.1145849
A33: transport, freight, sea, container ship | B33: 0.069333333 | C33: t-km | E33: =B33*150000 -> 10400
A34: Use phase *Please see note in top-corner* | B34: Directly Use Numbers Below
A35: Supply chain petrol, low-sulfur | B35: 0.061904762 | C35: kg
A36: Direct combustion | B36: 0.061904762 | C36: kg
A37: Disposal Determine using given information
A38: emulsion paint incineration | C38: kg
A39: glass incineration | C39: kg
A40: plastic mixture incineration | C40: kg
A41: zinc in car shredder residue incineration | C41: kg
...
